{
 "cells": [
  {
   "cell_type": "code",
   "execution_count": 1,
   "id": "02e62684",
   "metadata": {},
   "outputs": [],
   "source": [
    "import pandas as pd"
   ]
  },
  {
   "cell_type": "code",
   "execution_count": 2,
   "id": "cf1c08b9",
   "metadata": {},
   "outputs": [],
   "source": [
    "import numpy as np"
   ]
  },
  {
   "cell_type": "code",
   "execution_count": 8,
   "id": "565b7e99",
   "metadata": {},
   "outputs": [
    {
     "ename": "ModuleNotFoundError",
     "evalue": "No module named 'tensorflow'",
     "output_type": "error",
     "traceback": [
      "\u001b[1;31m---------------------------------------------------------------------------\u001b[0m",
      "\u001b[1;31mModuleNotFoundError\u001b[0m                       Traceback (most recent call last)",
      "\u001b[1;32m<ipython-input-8-f0637e1cf0ac>\u001b[0m in \u001b[0;36m<module>\u001b[1;34m\u001b[0m\n\u001b[1;32m----> 1\u001b[1;33m \u001b[1;32mfrom\u001b[0m \u001b[0mkeras\u001b[0m\u001b[1;33m.\u001b[0m\u001b[0mmodel\u001b[0m \u001b[1;32mimport\u001b[0m \u001b[0mSeqential\u001b[0m\u001b[1;33m\u001b[0m\u001b[1;33m\u001b[0m\u001b[0m\n\u001b[0m",
      "\u001b[1;32m~\\anaconda3\\lib\\site-packages\\keras\\__init__.py\u001b[0m in \u001b[0;36m<module>\u001b[1;34m\u001b[0m\n\u001b[0;32m     19\u001b[0m \"\"\"\n\u001b[0;32m     20\u001b[0m \u001b[1;31m# pylint: disable=unused-import\u001b[0m\u001b[1;33m\u001b[0m\u001b[1;33m\u001b[0m\u001b[1;33m\u001b[0m\u001b[0m\n\u001b[1;32m---> 21\u001b[1;33m \u001b[1;32mfrom\u001b[0m \u001b[0mtensorflow\u001b[0m\u001b[1;33m.\u001b[0m\u001b[0mpython\u001b[0m \u001b[1;32mimport\u001b[0m \u001b[0mtf2\u001b[0m\u001b[1;33m\u001b[0m\u001b[1;33m\u001b[0m\u001b[0m\n\u001b[0m\u001b[0;32m     22\u001b[0m \u001b[1;32mfrom\u001b[0m \u001b[0mkeras\u001b[0m \u001b[1;32mimport\u001b[0m \u001b[0mdistribute\u001b[0m\u001b[1;33m\u001b[0m\u001b[1;33m\u001b[0m\u001b[0m\n\u001b[0;32m     23\u001b[0m \u001b[1;33m\u001b[0m\u001b[0m\n",
      "\u001b[1;31mModuleNotFoundError\u001b[0m: No module named 'tensorflow'"
     ]
    }
   ],
   "source": [
    "from keras.model import Seqential"
   ]
  },
  {
   "cell_type": "code",
   "execution_count": 7,
   "id": "3f6f58dc",
   "metadata": {},
   "outputs": [
    {
     "name": "stdout",
     "output_type": "stream",
     "text": [
      "Object `keras` not found.\n"
     ]
    }
   ],
   "source": [
    "keras?"
   ]
  },
  {
   "cell_type": "code",
   "execution_count": 6,
   "id": "5e7230c3",
   "metadata": {},
   "outputs": [
    {
     "name": "stdout",
     "output_type": "stream",
     "text": [
      "Collecting keras\n",
      "  Downloading keras-2.9.0-py2.py3-none-any.whl (1.6 MB)\n",
      "Installing collected packages: keras\n",
      "Successfully installed keras-2.9.0\n"
     ]
    }
   ],
   "source": [
    "! pip install keras\n"
   ]
  },
  {
   "cell_type": "code",
   "execution_count": 1,
   "id": "72916dbf",
   "metadata": {},
   "outputs": [
    {
     "name": "stdout",
     "output_type": "stream",
     "text": [
      "Collecting tensorflow\n",
      "  Downloading tensorflow-2.9.1-cp38-cp38-win_amd64.whl (444.1 MB)\n"
     ]
    },
    {
     "name": "stderr",
     "output_type": "stream",
     "text": [
      "ERROR: Exception:\n",
      "Traceback (most recent call last):\n",
      "  File \"C:\\Users\\Dell\\anaconda3\\lib\\site-packages\\pip\\_vendor\\resolvelib\\resolvers.py\", line 171, in _merge_into_criterion\n",
      "    crit = self.state.criteria[name]\n",
      "KeyError: 'tensorflow'\n",
      "\n",
      "During handling of the above exception, another exception occurred:\n",
      "\n",
      "Traceback (most recent call last):\n",
      "  File \"C:\\Users\\Dell\\anaconda3\\lib\\site-packages\\pip\\_vendor\\urllib3\\response.py\", line 438, in _error_catcher\n",
      "    yield\n",
      "  File \"C:\\Users\\Dell\\anaconda3\\lib\\site-packages\\pip\\_vendor\\urllib3\\response.py\", line 519, in read\n",
      "    data = self._fp.read(amt) if not fp_closed else b\"\"\n",
      "  File \"C:\\Users\\Dell\\anaconda3\\lib\\site-packages\\pip\\_vendor\\cachecontrol\\filewrapper.py\", line 62, in read\n",
      "    data = self.__fp.read(amt)\n",
      "  File \"C:\\Users\\Dell\\anaconda3\\lib\\http\\client.py\", line 458, in read\n",
      "    n = self.readinto(b)\n",
      "  File \"C:\\Users\\Dell\\anaconda3\\lib\\http\\client.py\", line 502, in readinto\n",
      "    n = self.fp.readinto(b)\n",
      "  File \"C:\\Users\\Dell\\anaconda3\\lib\\socket.py\", line 669, in readinto\n",
      "    return self._sock.recv_into(b)\n",
      "  File \"C:\\Users\\Dell\\anaconda3\\lib\\ssl.py\", line 1241, in recv_into\n",
      "    return self.read(nbytes, buffer)\n",
      "  File \"C:\\Users\\Dell\\anaconda3\\lib\\ssl.py\", line 1099, in read\n",
      "    return self._sslobj.read(len, buffer)\n",
      "ConnectionResetError: [WinError 10054] An existing connection was forcibly closed by the remote host\n",
      "\n",
      "During handling of the above exception, another exception occurred:\n",
      "\n",
      "Traceback (most recent call last):\n",
      "  File \"C:\\Users\\Dell\\anaconda3\\lib\\site-packages\\pip\\_internal\\cli\\base_command.py\", line 189, in _main\n",
      "    status = self.run(options, args)\n",
      "  File \"C:\\Users\\Dell\\anaconda3\\lib\\site-packages\\pip\\_internal\\cli\\req_command.py\", line 178, in wrapper\n",
      "    return func(self, options, args)\n",
      "  File \"C:\\Users\\Dell\\anaconda3\\lib\\site-packages\\pip\\_internal\\commands\\install.py\", line 316, in run\n",
      "    requirement_set = resolver.resolve(\n",
      "  File \"C:\\Users\\Dell\\anaconda3\\lib\\site-packages\\pip\\_internal\\resolution\\resolvelib\\resolver.py\", line 121, in resolve\n",
      "    self._result = resolver.resolve(\n",
      "  File \"C:\\Users\\Dell\\anaconda3\\lib\\site-packages\\pip\\_vendor\\resolvelib\\resolvers.py\", line 453, in resolve\n",
      "    state = resolution.resolve(requirements, max_rounds=max_rounds)\n",
      "  File \"C:\\Users\\Dell\\anaconda3\\lib\\site-packages\\pip\\_vendor\\resolvelib\\resolvers.py\", line 318, in resolve\n",
      "    name, crit = self._merge_into_criterion(r, parent=None)\n",
      "  File \"C:\\Users\\Dell\\anaconda3\\lib\\site-packages\\pip\\_vendor\\resolvelib\\resolvers.py\", line 173, in _merge_into_criterion\n",
      "    crit = Criterion.from_requirement(self._p, requirement, parent)\n",
      "  File \"C:\\Users\\Dell\\anaconda3\\lib\\site-packages\\pip\\_vendor\\resolvelib\\resolvers.py\", line 82, in from_requirement\n",
      "    if not cands:\n",
      "  File \"C:\\Users\\Dell\\anaconda3\\lib\\site-packages\\pip\\_vendor\\resolvelib\\structs.py\", line 124, in __bool__\n",
      "    return bool(self._sequence)\n",
      "  File \"C:\\Users\\Dell\\anaconda3\\lib\\site-packages\\pip\\_internal\\resolution\\resolvelib\\found_candidates.py\", line 143, in __bool__\n",
      "    return any(self)\n",
      "  File \"C:\\Users\\Dell\\anaconda3\\lib\\site-packages\\pip\\_internal\\resolution\\resolvelib\\found_candidates.py\", line 38, in _iter_built\n",
      "    candidate = func()\n",
      "  File \"C:\\Users\\Dell\\anaconda3\\lib\\site-packages\\pip\\_internal\\resolution\\resolvelib\\factory.py\", line 167, in _make_candidate_from_link\n",
      "    self._link_candidate_cache[link] = LinkCandidate(\n",
      "  File \"C:\\Users\\Dell\\anaconda3\\lib\\site-packages\\pip\\_internal\\resolution\\resolvelib\\candidates.py\", line 300, in __init__\n",
      "    super().__init__(\n",
      "  File \"C:\\Users\\Dell\\anaconda3\\lib\\site-packages\\pip\\_internal\\resolution\\resolvelib\\candidates.py\", line 144, in __init__\n",
      "    self.dist = self._prepare()\n",
      "  File \"C:\\Users\\Dell\\anaconda3\\lib\\site-packages\\pip\\_internal\\resolution\\resolvelib\\candidates.py\", line 226, in _prepare\n",
      "    dist = self._prepare_distribution()\n",
      "  File \"C:\\Users\\Dell\\anaconda3\\lib\\site-packages\\pip\\_internal\\resolution\\resolvelib\\candidates.py\", line 311, in _prepare_distribution\n",
      "    return self._factory.preparer.prepare_linked_requirement(\n",
      "  File \"C:\\Users\\Dell\\anaconda3\\lib\\site-packages\\pip\\_internal\\operations\\prepare.py\", line 457, in prepare_linked_requirement\n",
      "    return self._prepare_linked_requirement(req, parallel_builds)\n",
      "  File \"C:\\Users\\Dell\\anaconda3\\lib\\site-packages\\pip\\_internal\\operations\\prepare.py\", line 480, in _prepare_linked_requirement\n",
      "    local_file = unpack_url(\n",
      "  File \"C:\\Users\\Dell\\anaconda3\\lib\\site-packages\\pip\\_internal\\operations\\prepare.py\", line 230, in unpack_url\n",
      "    file = get_http_url(\n",
      "  File \"C:\\Users\\Dell\\anaconda3\\lib\\site-packages\\pip\\_internal\\operations\\prepare.py\", line 108, in get_http_url\n",
      "    from_path, content_type = download(link, temp_dir.path)\n",
      "  File \"C:\\Users\\Dell\\anaconda3\\lib\\site-packages\\pip\\_internal\\network\\download.py\", line 163, in __call__\n",
      "    for chunk in chunks:\n",
      "  File \"C:\\Users\\Dell\\anaconda3\\lib\\site-packages\\pip\\_internal\\cli\\progress_bars.py\", line 159, in iter\n",
      "    for x in it:\n",
      "  File \"C:\\Users\\Dell\\anaconda3\\lib\\site-packages\\pip\\_internal\\network\\utils.py\", line 64, in response_chunks\n",
      "    for chunk in response.raw.stream(\n",
      "  File \"C:\\Users\\Dell\\anaconda3\\lib\\site-packages\\pip\\_vendor\\urllib3\\response.py\", line 576, in stream\n",
      "    data = self.read(amt=amt, decode_content=decode_content)\n",
      "  File \"C:\\Users\\Dell\\anaconda3\\lib\\site-packages\\pip\\_vendor\\urllib3\\response.py\", line 541, in read\n",
      "    raise IncompleteRead(self._fp_bytes_read, self.length_remaining)\n",
      "  File \"C:\\Users\\Dell\\anaconda3\\lib\\contextlib.py\", line 131, in __exit__\n",
      "    self.gen.throw(type, value, traceback)\n",
      "  File \"C:\\Users\\Dell\\anaconda3\\lib\\site-packages\\pip\\_vendor\\urllib3\\response.py\", line 455, in _error_catcher\n",
      "    raise ProtocolError(\"Connection broken: %r\" % e, e)\n",
      "pip._vendor.urllib3.exceptions.ProtocolError: (\"Connection broken: ConnectionResetError(10054, 'An existing connection was forcibly closed by the remote host', None, 10054, None)\", ConnectionResetError(10054, 'An existing connection was forcibly closed by the remote host', None, 10054, None))\n"
     ]
    }
   ],
   "source": [
    "!pip install tensorflow"
   ]
  },
  {
   "cell_type": "code",
   "execution_count": 2,
   "id": "69a89b06",
   "metadata": {},
   "outputs": [
    {
     "name": "stderr",
     "output_type": "stream",
     "text": [
      "'py' is not recognized as an internal or external command,\n",
      "operable program or batch file.\n"
     ]
    }
   ],
   "source": [
    "! py -3.7-64 -m pip install --default-timeout=100 tensorflow"
   ]
  },
  {
   "cell_type": "code",
   "execution_count": 5,
   "id": "bf7cbd03",
   "metadata": {},
   "outputs": [
    {
     "name": "stdout",
     "output_type": "stream",
     "text": [
      "Collecting tensorflow\n",
      "  Downloading tensorflow-2.9.1-cp38-cp38-win_amd64.whl (444.1 MB)\n",
      "Note: you may need to restart the kernel to use updated packages.\n"
     ]
    },
    {
     "name": "stderr",
     "output_type": "stream",
     "text": [
      "ERROR: Exception:\n",
      "Traceback (most recent call last):\n",
      "  File \"C:\\Users\\Dell\\anaconda3\\lib\\site-packages\\pip\\_vendor\\resolvelib\\resolvers.py\", line 171, in _merge_into_criterion\n",
      "    crit = self.state.criteria[name]\n",
      "KeyError: 'tensorflow'\n",
      "\n",
      "During handling of the above exception, another exception occurred:\n",
      "\n",
      "Traceback (most recent call last):\n",
      "  File \"C:\\Users\\Dell\\anaconda3\\lib\\site-packages\\pip\\_vendor\\urllib3\\response.py\", line 438, in _error_catcher\n",
      "    yield\n",
      "  File \"C:\\Users\\Dell\\anaconda3\\lib\\site-packages\\pip\\_vendor\\urllib3\\response.py\", line 519, in read\n",
      "    data = self._fp.read(amt) if not fp_closed else b\"\"\n",
      "  File \"C:\\Users\\Dell\\anaconda3\\lib\\site-packages\\pip\\_vendor\\cachecontrol\\filewrapper.py\", line 62, in read\n",
      "    data = self.__fp.read(amt)\n",
      "  File \"C:\\Users\\Dell\\anaconda3\\lib\\http\\client.py\", line 458, in read\n",
      "    n = self.readinto(b)\n",
      "  File \"C:\\Users\\Dell\\anaconda3\\lib\\http\\client.py\", line 502, in readinto\n",
      "    n = self.fp.readinto(b)\n",
      "  File \"C:\\Users\\Dell\\anaconda3\\lib\\socket.py\", line 669, in readinto\n",
      "    return self._sock.recv_into(b)\n",
      "  File \"C:\\Users\\Dell\\anaconda3\\lib\\ssl.py\", line 1241, in recv_into\n",
      "    return self.read(nbytes, buffer)\n",
      "  File \"C:\\Users\\Dell\\anaconda3\\lib\\ssl.py\", line 1099, in read\n",
      "    return self._sslobj.read(len, buffer)\n",
      "ConnectionResetError: [WinError 10054] An existing connection was forcibly closed by the remote host\n",
      "\n",
      "During handling of the above exception, another exception occurred:\n",
      "\n",
      "Traceback (most recent call last):\n",
      "  File \"C:\\Users\\Dell\\anaconda3\\lib\\site-packages\\pip\\_internal\\cli\\base_command.py\", line 189, in _main\n",
      "    status = self.run(options, args)\n",
      "  File \"C:\\Users\\Dell\\anaconda3\\lib\\site-packages\\pip\\_internal\\cli\\req_command.py\", line 178, in wrapper\n",
      "    return func(self, options, args)\n",
      "  File \"C:\\Users\\Dell\\anaconda3\\lib\\site-packages\\pip\\_internal\\commands\\install.py\", line 316, in run\n",
      "    requirement_set = resolver.resolve(\n",
      "  File \"C:\\Users\\Dell\\anaconda3\\lib\\site-packages\\pip\\_internal\\resolution\\resolvelib\\resolver.py\", line 121, in resolve\n",
      "    self._result = resolver.resolve(\n",
      "  File \"C:\\Users\\Dell\\anaconda3\\lib\\site-packages\\pip\\_vendor\\resolvelib\\resolvers.py\", line 453, in resolve\n",
      "    state = resolution.resolve(requirements, max_rounds=max_rounds)\n",
      "  File \"C:\\Users\\Dell\\anaconda3\\lib\\site-packages\\pip\\_vendor\\resolvelib\\resolvers.py\", line 318, in resolve\n",
      "    name, crit = self._merge_into_criterion(r, parent=None)\n",
      "  File \"C:\\Users\\Dell\\anaconda3\\lib\\site-packages\\pip\\_vendor\\resolvelib\\resolvers.py\", line 173, in _merge_into_criterion\n",
      "    crit = Criterion.from_requirement(self._p, requirement, parent)\n",
      "  File \"C:\\Users\\Dell\\anaconda3\\lib\\site-packages\\pip\\_vendor\\resolvelib\\resolvers.py\", line 82, in from_requirement\n",
      "    if not cands:\n",
      "  File \"C:\\Users\\Dell\\anaconda3\\lib\\site-packages\\pip\\_vendor\\resolvelib\\structs.py\", line 124, in __bool__\n",
      "    return bool(self._sequence)\n",
      "  File \"C:\\Users\\Dell\\anaconda3\\lib\\site-packages\\pip\\_internal\\resolution\\resolvelib\\found_candidates.py\", line 143, in __bool__\n",
      "    return any(self)\n",
      "  File \"C:\\Users\\Dell\\anaconda3\\lib\\site-packages\\pip\\_internal\\resolution\\resolvelib\\found_candidates.py\", line 38, in _iter_built\n",
      "    candidate = func()\n",
      "  File \"C:\\Users\\Dell\\anaconda3\\lib\\site-packages\\pip\\_internal\\resolution\\resolvelib\\factory.py\", line 167, in _make_candidate_from_link\n",
      "    self._link_candidate_cache[link] = LinkCandidate(\n",
      "  File \"C:\\Users\\Dell\\anaconda3\\lib\\site-packages\\pip\\_internal\\resolution\\resolvelib\\candidates.py\", line 300, in __init__\n",
      "    super().__init__(\n",
      "  File \"C:\\Users\\Dell\\anaconda3\\lib\\site-packages\\pip\\_internal\\resolution\\resolvelib\\candidates.py\", line 144, in __init__\n",
      "    self.dist = self._prepare()\n",
      "  File \"C:\\Users\\Dell\\anaconda3\\lib\\site-packages\\pip\\_internal\\resolution\\resolvelib\\candidates.py\", line 226, in _prepare\n",
      "    dist = self._prepare_distribution()\n",
      "  File \"C:\\Users\\Dell\\anaconda3\\lib\\site-packages\\pip\\_internal\\resolution\\resolvelib\\candidates.py\", line 311, in _prepare_distribution\n",
      "    return self._factory.preparer.prepare_linked_requirement(\n",
      "  File \"C:\\Users\\Dell\\anaconda3\\lib\\site-packages\\pip\\_internal\\operations\\prepare.py\", line 457, in prepare_linked_requirement\n",
      "    return self._prepare_linked_requirement(req, parallel_builds)\n",
      "  File \"C:\\Users\\Dell\\anaconda3\\lib\\site-packages\\pip\\_internal\\operations\\prepare.py\", line 480, in _prepare_linked_requirement\n",
      "    local_file = unpack_url(\n",
      "  File \"C:\\Users\\Dell\\anaconda3\\lib\\site-packages\\pip\\_internal\\operations\\prepare.py\", line 230, in unpack_url\n",
      "    file = get_http_url(\n",
      "  File \"C:\\Users\\Dell\\anaconda3\\lib\\site-packages\\pip\\_internal\\operations\\prepare.py\", line 108, in get_http_url\n",
      "    from_path, content_type = download(link, temp_dir.path)\n",
      "  File \"C:\\Users\\Dell\\anaconda3\\lib\\site-packages\\pip\\_internal\\network\\download.py\", line 163, in __call__\n",
      "    for chunk in chunks:\n",
      "  File \"C:\\Users\\Dell\\anaconda3\\lib\\site-packages\\pip\\_internal\\cli\\progress_bars.py\", line 159, in iter\n",
      "    for x in it:\n",
      "  File \"C:\\Users\\Dell\\anaconda3\\lib\\site-packages\\pip\\_internal\\network\\utils.py\", line 64, in response_chunks\n",
      "    for chunk in response.raw.stream(\n",
      "  File \"C:\\Users\\Dell\\anaconda3\\lib\\site-packages\\pip\\_vendor\\urllib3\\response.py\", line 576, in stream\n",
      "    data = self.read(amt=amt, decode_content=decode_content)\n",
      "  File \"C:\\Users\\Dell\\anaconda3\\lib\\site-packages\\pip\\_vendor\\urllib3\\response.py\", line 541, in read\n",
      "    raise IncompleteRead(self._fp_bytes_read, self.length_remaining)\n",
      "  File \"C:\\Users\\Dell\\anaconda3\\lib\\contextlib.py\", line 131, in __exit__\n",
      "    self.gen.throw(type, value, traceback)\n",
      "  File \"C:\\Users\\Dell\\anaconda3\\lib\\site-packages\\pip\\_vendor\\urllib3\\response.py\", line 455, in _error_catcher\n",
      "    raise ProtocolError(\"Connection broken: %r\" % e, e)\n",
      "pip._vendor.urllib3.exceptions.ProtocolError: (\"Connection broken: ConnectionResetError(10054, 'An existing connection was forcibly closed by the remote host', None, 10054, None)\", ConnectionResetError(10054, 'An existing connection was forcibly closed by the remote host', None, 10054, None))\n"
     ]
    }
   ],
   "source": [
    "pip install --default-timeout=100 tensorflow"
   ]
  },
  {
   "cell_type": "code",
   "execution_count": null,
   "id": "f258679d",
   "metadata": {},
   "outputs": [],
   "source": []
  }
 ],
 "metadata": {
  "kernelspec": {
   "display_name": "Python 3",
   "language": "python",
   "name": "python3"
  },
  "language_info": {
   "codemirror_mode": {
    "name": "ipython",
    "version": 3
   },
   "file_extension": ".py",
   "mimetype": "text/x-python",
   "name": "python",
   "nbconvert_exporter": "python",
   "pygments_lexer": "ipython3",
   "version": "3.8.8"
  }
 },
 "nbformat": 4,
 "nbformat_minor": 5
}
